Workbook

Sheet Lisez-moi
B1: Mon Écran · classeur de configuration (version 2)
B3: À quoi sert ce classeur
B4: Il décrit tout ce que ton dock affiche : compétitions de sport, rubriques et médias d'actus, marchés, plateformes vidéo, chaînes YouTube, chaînes TV, cotes, pages, widgets et thèmes. Tu coches, tu déposes le fichier sur GitHub, et le dock se règle tout seul.
B5: Les lignes déjà cochées correspondent exactement au dock actuel. Le reste est un catalogue de ce que le dock sait récupérer : il suffit de cocher.
B6: En 4 étapes
B7: 1. Ouvre un onglet (Sport, Actus, Marchés…). Mets « Oui » dans la colonne jaune des lignes que tu veux, « Non » pour en exclure une d'une section entière.
B8: 2. Pour ajouter quelque chose qui n'est pas listé, va tout en bas de l'onglet, bloc « MES AJOUTS ». Une rubrique, une région ou un thème qui n'existe pas encore crée une nouvelle section.
B9: 3. Enregistre le fichier sous le nom configuration.xlsx et dépose-le à la racine de ton dépôt GitHub (détail dans l'onglet Tuto).
B10: 4. La tâche GitHub « Configuration » lit le classeur, écrit les réglages du dock, teste les nouveautés et range une copie avec la colonne « Résultat » remplie (config/configuration-resultat.xlsx). Le résumé s'affiche aussi dans la page État de l'appli.
B11: Règles de sélection
B12: • « Oui » sur la ligne « ▸ toute la section » prend tous les éléments de la section, sauf ceux marqués « Non ».
B13: • « Oui » sur un seul élément suffit : sa section apparaît dans l'appli avec cet élément seulement.
... B21: Légende
C22: Case à remplir : « Oui », « Non » ou vide
C23: Ligne choisie (se colore toute seule)
C24: Ligne de section : « ▸ toute la section »
C25: Résultat : ✅ fonctionne · ⚠️ trouvé, à vérifier · ❌ introuvable · « à vérifier » = pas encore testé
B27: Synthèse de tes choix (calculée automatiquement)
B28: Onglet | C28: Éléments cochés | D28: Disponibles | E28: Contenu
B29: Sport | C29: =COUNTIFS(Sport!$H$6:$H$157,"Oui",Sport!$A$6:$A$157,"<>sec:*") -> 41 | D29: =COUNTIFS(Sport!$A$6:$A$157,"<>sec:*",Sport!$A$6:$A$157,"<>") -> 135 | E29: Sport · compétitions suivies
B30: Équipes favorites | C30: =COUNTIFS('Équipes favorites'!$D$6:$D$65,"Oui",'Équipes favorites'!$A$6:$A$65,"<>sec:*") -> 12 | D30: =COUNTIFS('Équipes favorites'!$A$6:$A$65,"<>sec:*",'Équipes favorites'!$A$6:$A$65,"<>") -> 54 | E30: Sport · équipes favorites
B31: Actus | C31: =COUNTIFS(Actus!$F$6:$F$231,"Oui",Actus!$A$6:$A$231,"<>sec:*") -> 33 | D31: =COUNTIFS(Actus!$A$6:$A$231,"<>sec:*",Actus!$A$6:$A$231,"<>") -> 201 | E31: Actus · rubriques et médias (français)
B32: Actus International | C32: =COUNTIFS('Actus International'!$F$6:$F$105,"Oui",'Actus International'!$A$6:$A$105,"<>sec:*") -> 25 | D32: =COUNTIFS('Actus International'!$A$6:$A$105,"<>sec:*",'Actus International'!$A$6:$A$105,"<>") -> 85 | E32: Actus · mode International (anglais)
B33: Marchés | C33: =COUNTIFS(Marchés!$G$6:$G$83,"Oui",Marchés!$A$6:$A$83,"<>sec:*") -> 12 | D33: =COUNTIFS(Marchés!$A$6:$A$83,"<>sec:*",Marchés!$A$6:$A$83,"<>") -> 70 | E33: Investissements · marchés et fonds suivis
B34: Vidéos | C34: =COUNTIFS(Vidéos!$G$6:$G$26,"Oui",Vidéos!$A$6:$A$26,"<>sec:*") -> 7 | D34: =COUNTIFS(Vidéos!$A$6:$A$26,"<>sec:*",Vidéos!$A$6:$A$26,"<>") -> 20 | E34: Vidéos · plateformes de streaming
B35: YouTube | C35: =COUNTIFS(YouTube!$E$6:$E$60,"Oui",YouTube!$A$6:$A$60,"<>sec:*") -> 2 | D35: =COUNTIFS(YouTube!$A$6:$A$60,"<>sec:*",YouTube!$A$6:$A$60,"<>") -> 45 | E35: Vidéos · chaînes YouTube
B36: Programme TV | C36: =COUNTIFS('Programme TV'!$E$6:$E$83,"Oui",'Programme TV'!$A$6:$A$83,"<>sec:*") -> 55 | D36: =COUNTIFS('Programme TV'!$A$6:$A$83,"<>sec:*",'Programme TV'!$A$6:$A$83,"<>") -> 72 | E36: Programme TV · chaînes lues pour les matchs
B37: Cotes | C37: =COUNTIFS(Cotes!$F$6:$F$48,"Oui",Cotes!$A$6:$A$48,"<>sec:*") -> 15 | D37: =COUNTIFS(Cotes!$A$6:$A$48,"<>sec:*",Cotes!$A$6:$A$48,"<>") -> 39 | E37: Cotes des matchs · sites et compétitions
B38: Accueil | C38: =COUNTIFS(Accueil!$E$6:$E$37,"Oui",Accueil!$A$6:$A$37,"<>sec:*") -> 18 | D38: =COUNTIFS(Accueil!$A$6:$A$37,"<>sec:*",Accueil!$A$6:$A$37,"<>") -> 28 | E38: Accueil · pages, widgets et météo
B39: Applis | C39: =COUNTIFS(Applis!$G$6:$G$54,"Oui",Applis!$A$6:$A$54,"<>sec:*") -> 41 | D39: =COUNTIFS(Applis!$A$6:$A$54,"<>sec:*",Applis!$A$6:$A$54,"<>") -> 41 | E39: Accueil · applis, dossiers et liens
B40: Apparence | C40: =COUNTIFS(Apparence!$E$6:$E$17,"Oui",Apparence!$A$6:$A$17,"<>sec:*") -> 8 | D40: =COUNTIFS(Apparence!$A$6:$A$17,"<>sec:*",Apparence!$A$6:$A$17,"<>") -> 10 | E40: Apparence · thèmes et mode
B41: Total | C41: =SUM(C29:C40) -> 269 | D41: =SUM(D29:D40) -> 800
B43: Journal des versions du classeur
B44: Version 1 | C44: 30/10/2026 | D44: Première version : 11 onglets (Sport, Équipes favorites, Actus, Actus International, Marchés, Vidéos, YouTube, Programme TV, Cotes, Accueil, Apparence), pré-cochés à l'identique du dock actuel, catalogue de plus de 500 éléments à essayer, blocs « Mes ajouts », Tuto.
B45: Version 2 | C45: 30/10/2026 | D45: Onglet Applis : dossiers, bandeau du bas et navigation, avec 3 liens par appli (iPhone, Android, web) modifiables. Onglet Cotes : réglages du rapport des écarts. Les pages lisent désormais ces réglages (config/config.js).

Sheet Tuto
B1: Tuto · remplir le classeur et installer sa propre version
B3: Partie 1 · Remplir et déposer le classeur
B4: Pour tout le monde, à chaque changement de réglages.
B5: N° | C5: Étape | D5: Où | E5: Comment
B6: 1 | C6: Ouvrir le classeur | D6: Excel, Numbers ou Google Sheets | E6: Sur iPhone, Numbers ou l'appli Excel conviennent. Les colonnes jaunes sont les seules à remplir.
B7: 2 | C7: Cocher ce que tu veux | D7: Onglets Sport, Actus, Marchés… | E7: « Oui » dans la colonne Oui. « Non » pour exclure un élément d'une section prise en entier. Laisse vide pour ne rien changer.
B8: 3 | C8: Ajouter un élément absent | D8: Bas de chaque onglet, bloc MES AJOUTS | E8: Remplis Section (existante ou nouvelle), Nom et Source (adresse d'un site, @nom YouTube, ISIN, clé ESPN…), puis « Oui ». La ligne d'exemple grise est ignorée.
B9: 4 | C9: Vérifier la synthèse | D9: Onglet Lisez-moi | E9: Le tableau compte tes éléments cochés par onglet : un moyen rapide de voir si rien n'a été oublié.
B10: 5 | C10: Enregistrer | D10: Format .xlsx | E10: Nom du fichier : configuration.xlsx (exactement). Garde le format Excel, pas .numbers ni .csv.
B11: 6 | C11: Déposer sur GitHub | D11: Page de ton dépôt GitHub | E11: Sur la page du dépôt : Add file → Upload files → glisse configuration.xlsx → Commit changes. Il remplace l'ancien.
B12: 7 | C12: Suivre la tâche | D12: Onglet Actions du dépôt | E12: La tâche « Configuration » démarre seule (1 à 3 minutes). Coche verte = réglages appliqués ; croix rouge = ouvre-la pour lire l'erreur.
B13: 8 | C13: Lire le résultat | D13: Page État de l'appli, ou config/configuration-resultat.xlsx | E13: Chaque nouveauté reçoit ✅ (fonctionne), ⚠️ (trouvé, à vérifier) ou ❌ (introuvable, avec la raison). Corrige et redépose si besoin.
B15: Partie 2 · Installer sa propre version (une seule fois)
B16: Pour un ami qui veut son dock à lui. Compter 30 à 45 minutes. Rien de payant.
B17: N° | C17: Étape | D17: Où | E17: Comment
B18: 1 | C18: Créer un compte GitHub | D18: github.com | E18: Gratuit. Choisis un pseudo : il apparaîtra dans l'adresse du dock (https://pseudo.github.io/…).
B19: 2 | C19: Copier le dépôt | D19: Dépôt d'origine (lien) | E19: Bouton « Fork » → garde le même nom → Create fork. Tu as maintenant ta propre copie.
B20: 3 | C20: Activer les tâches | D20: Ta copie → onglet Actions | E20: Sur une copie, GitHub les désactive : bouton « I understand my workflows, go ahead and enable them ».
B21: 4 | C21: Publier le site | D21: Settings → Pages | E21: Source : GitHub Actions. Après la première tâche « Publication », le dock est en ligne à l'adresse affichée en haut de cette page.
B22: 5 | C22: Autoriser les tâches à écrire | D22: Settings → Actions → General | E22: Tout en bas, Workflow permissions : « Read and write permissions » → Save. Sans ça, les données ne peuvent pas être enregistrées.
B23: 6 | C23: Clé TMDB (catalogue vidéo) | D23: themoviedb.org | E23: Crée un compte, puis Paramètres → API → demande une clé « Developer » (usage personnel, gratuit). Copie le long « API Read Access Token » (commence par eyJ…).
B24: 7 | C24: Enregistrer la clé TMDB | D24: Settings → Secrets and variables → Actions | E24: New repository secret : nom TMDB_TOKEN, valeur = le jeton copié. Les secrets ne sont jamais visibles publiquement.
B25: 8 | C25: Clé des cotes (facultatif) | D25: the-odds-api.com | E25: Offre gratuite (500 crédits par mois) : la clé arrive par e-mail. Secret GitHub ODDS_API_KEY. Pour l'actualisation à la main, colle aussi la clé dans État → Cotes des matchs (elle reste sur l'appareil).
B26: 9 | C26: Lancer les tâches une première fois | D26: Onglet Actions | E26: Ouvre chaque tâche (Actus, Marchés, Vidéos, Programme TV sport, Cotes, Publication) → Run workflow. Ensuite elles tournent seules.
B27: 10 | C27: Ajouter le dock à l'iPhone | D27: Safari, sur l'adresse du dock | E27: Bouton Partager → « Sur l'écran d'accueil ». Le dock s'ouvre alors en plein écran comme une appli.
B28: 11 | C28: Choisir son code | D28: Page Investissements ou Coffre | E28: Au premier usage, l'appli demande un code PIN : il chiffre tes montants et ton coffre sur l'appareil. Il n'est jamais envoyé nulle part.
B29: 12 | C29: Synchroniser ses appareils (facultatif) | D29: État → Synchronisation | E29: Crée une clé GitHub « fine-grained » (Repository access : seulement ta copie ; Permissions → Contents : Read and write), puis suis l'assistant : il génère une phrase de 6 mots à garder précieusement. Note : aujourd'hui l'adresse du dépôt de synchronisation est écrite dans synchro.js ; elle passera dans la configuration lors du branchement des pages.
... B31: 14 | C31: Déposer ton classeur | D31: Partie 1, étapes 5 à 8 | E31: Décoche ce qui ne t'intéresse pas (les choix de départ sont ceux de Yoann), ajoute tes équipes, tes villes, tes fonds, puis dépose configuration.xlsx.
B33: Mises à jour de l'appli
B34: Quand une nouvelle version du dock est publiée.
B35: N° | C35: Étape | D35: Où | E35: Comment
B36: 1 | C36: Récupérer la mise à jour | D36: Fichier mise-a-jour-vNN.zip | E36: Dépose-le à la racine de ta copie (Add file → Upload files). La tâche « Mise à jour » l'installe toute seule.
B37: 2 | C37: Fichiers de tâches | D37: Dossier .github/workflows | E37: GitHub interdit aux tâches de modifier ce dossier : si la mise à jour en contient, la tâche les liste et il faut les déposer à la main dans .github/workflows.
B38: 3 | C38: Tes réglages restent | D38: configuration.xlsx | E38: Une mise à jour ne touche jamais tes choix. Si une nouvelle version du classeur est livrée, tes choix sont repris par identifiant.

Sheet Sport
A1: module=sport;version=2 | B1: Sport · compétitions suivies
B2: Coche « Oui » pour afficher une compétition dans la page Sport. « Favori » la met en avant (comme la F1 et le MotoGP aujourd'hui). « Prise en charge » : Oui = l'appli sait déjà l'afficher · À développer = données disponibles, affichage à coder · Non disponible = pas de source gratuite fiable.
B3: À remplir : cases jaunes (« Oui » ou « Non »). Ligne « ▸ toute la section » = tous ses éléments, sauf ceux marqués « Non ». Un seul élément coché suffit pour que sa section apparaisse. Colonne « Résultat » : remplie par la tâche GitHub après dépôt du classeur.
A5: ID | B5: Section | C5: Compétition | D5: Sport | E5: Clé ESPN | F5: Diffuseur(s) en France | G5: Prise en charge | H5: Oui | I5: Favori | J5: Résultat | K5: Note | L5: Technique
A6: sec:sport:fr | B6: France | C6: ▸ toute la section | L6: {"id": "fr", "label": "France"}
A7: sp:fra.1 | B7: France | C7: Ligue 1 | D7: soccer | E7: fra.1 | F7: Ligue 1+ | G7: Oui | H7: Oui | L7: {"support": "ok", "def": {"id": "fra.1", "region": "fr", "flag": "🇫🇷", "sport": "soccer", "group": "foot", "name": "Ligue 1", "tv": ["Ligue 1+"], "rounds": true, "of": "fr.1"}}
A8: sp:fra.2 | B8: France | C8: Ligue 2 | D8: soccer | E8: fra.2 | F8: beIN Sports | G8: Oui | H8: Oui | L8: {"support": "ok", "def": {"id": "fra.2", "region": "fr", "flag": "🇫🇷", "sport": "soccer", "group": "foot", "name": "Ligue 2", "tv": ["beIN Sports"], "rounds": true, "of": "fr.2", "tsdb": {"c": "France", "s": "Soccer", "re": {"re": "ligue 2", "flags": "i"}}}}
A9: sp:fra.coupe_de_france | B9: France | C9: Coupe de France | D9: soccer | E9: fra.coupe_de_france | F9: beIN Sports | G9: Oui | H9: Oui | L9: {"support": "ok", "def": {"id": "fra.coupe_de_france", "region": "fr", "flag": "🇫🇷", "sport": "soccer", "group": "foot", "name": "Coupe de France", "tv": ["beIN Sports"]}}
A10: sp:fra.super_cup | B10: France | C10: Trophée des champions | D10: soccer | E10: fra.super_cup | G10: Oui | H10: Oui | L10: {"support": "ok", "def": {"id": "fra.super_cup", "region": "fr", "flag": "🇫🇷", "sport": "soccer", "group": "foot", "name": "Trophée des champions", "seasonal": true}}
A11: sp:fra.3 | B11: France | C11: National | D11: soccer | E11: fra.3 | G11: Oui | J11: à vérifier | L11: {"support": "ok", "def": {"id": "fra.3", "region": "fr", "flag": "🇫🇷", "sport": "soccer", "group": "foot", "name": "National"}}
A12: sec:sport:ec | B12: Compétitions européennes | C12: ▸ toute la section | L12: {"id": "ec", "label": "Compétitions européennes"}
A13: sp:uefa.champions | B13: Compétitions européennes | C13: Ligue des champions | D13: soccer | E13: uefa.champions | F13: Canal+ | G13: Oui | H13: Oui | L13: {"support": "ok", "def": {"id": "uefa.champions", "region": "ec", "flag": "🇪🇺", "sport": "soccer", "group": "foot", "name": "Ligue des champions", "tv": ["Canal+"]}}
A14: sp:uefa.europa | B14: Compétitions européennes | C14: Ligue Europa | D14: soccer | E14: uefa.europa | F14: Canal+ | G14: Oui | H14: Oui | L14: {"support": "ok", "def": {"id": "uefa.europa", "region": "ec", "flag": "🇪🇺", "sport": "soccer", "group": "foot", "name": "Ligue Europa", "tv": ["Canal+"]}}
A15: sp:uefa.europa.conf | B15: Compétitions européennes | C15: Ligue Conférence | D15: soccer | E15: uefa.europa.conf | F15: Canal+ | G15: Oui | H15: Oui | L15: {"support": "ok", "def": {"id": "uefa.europa.conf", "region": "ec", "flag": "🇪🇺", "sport": "soccer", "group": "foot", "name": "Ligue Conférence", "tv": ["Canal+"]}}
A16: sp:uefa.super_cup | B16: Compétitions européennes | C16: Supercoupe d'Europe | D16: soccer | E16: uefa.super_cup | G16: Oui | H16: Oui | L16: {"support": "ok", "def": {"id": "uefa.super_cup", "region": "ec", "flag": "🇪🇺", "sport": "soccer", "group": "foot", "name": "Supercoupe d'Europe", "seasonal": true}}
A17: sp:uefa.champions_qual | B17: Compétitions européennes | C17: Ligue des champions · qualifications | D17: soccer | E17: uefa.champions_qual | G17: Oui | J17: à vérifier | L17: {"support": "ok", "def": {"id": "uefa.champions_qual", "region": "ec", "flag": "🇪🇺", "sport": "soccer", "group": "foot", "name": "Ligue des champions · qualifications"}}
A18: sp:uefa.europa_qual | B18: Compétitions européennes | C18: Ligue Europa · qualifications | D18: soccer | E18: uefa.europa_qual | G18: Oui | J18: à vérifier | L18: {"support": "ok", "def": {"id": "uefa.europa_qual", "region": "ec", "flag": "🇪🇺", "sport": "soccer", "group": "foot", "name": "Ligue Europa · qualifications"}}
A19: sp:uefa.europa.conf_qual | B19: Compétitions européennes | C19: Ligue Conférence · qualifications | D19: soccer | E19: uefa.europa.conf_qual | G19: Oui | J19: à vérifier | L19: {"support": "ok", "def": {"id": "uefa.europa.conf_qual", "region": "ec", "flag": "🇪🇺", "sport": "soccer", "group": "foot", "name": "Ligue Conférence · qualifications"}}
A20: sp:uefa.youth_league | B20: Compétitions européennes | C20: UEFA Youth League | D20: soccer | E20: uefa.youth_league | G20: Oui | J20: à vérifier | L20: {"support": "ok", "def": {"id": "uefa.youth_league", "region": "ec", "flag": "🇪🇺", "sport": "soccer", "group": "foot", "name": "UEFA Youth League"}}
A21: sec:sport:intl | B21: Football international | C21: ▸ toute la section | L21: {"id": "intl", "label": "Football international"}
A22: sp:fifa.world | B22: Football international | C22: Coupe du monde | D22: soccer | E22: fifa.world | G22: Oui | H22: Oui | L22: {"support": "ok", "def": {"id": "fifa.world", "region": "intl", "flag": "🌍", "sport": "soccer", "group": "foot", "name": "Coupe du monde", "seasonal": true}}
A23: sp:uefa.euro | B23: Football international | C23: Euro | D23: soccer | E23: uefa.euro | G23: Oui | H23: Oui | L23: {"support": "ok", "def": {"id": "uefa.euro", "region": "intl", "flag": "🇪🇺", "sport": "soccer", "group": "foot", "name": "Euro", "seasonal": true}}
A24: sp:fifa.worldq.uefa | B24: Football international | C24: Qualifications Coupe du monde | D24: soccer | E24: fifa.worldq.uefa | F24: TF1 | G24: Oui | H24: Oui | L24: {"support": "ok", "def": {"id": "fifa.worldq.uefa", "region": "intl", "flag": "🌍", "sport": "soccer", "group": "foot", "name": "Qualifications Coupe du monde", "tv": ["TF1"], "tvTeam": "France", "seasonal": true}}
A25: sp:uefa.euroq | B25: Football international | C25: Qualifications Euro | D25: soccer | E25: uefa.euroq | F25: TF1 | G25: Oui | H25: Oui | L25: {"support": "ok", "def": {"id": "uefa.euroq", "region": "intl", "flag": "🇪🇺", "sport": "soccer", "group": "foot", "name": "Qualifications Euro", "tv": ["TF1"], "tvTeam": "France", "seasonal": true}}
A26: sp:uefa.nations | B26: Football international | C26: Ligue des nations | D26: soccer | E26: uefa.nations | F26: TF1 | G26: Oui | H26: Oui | L26: {"support": "ok", "def": {"id": "uefa.nations", "region": "intl", "flag": "🇪🇺", "sport": "soccer", "group": "foot", "name": "Ligue des nations", "tv": ["TF1"], "tvTeam": "France", "seasonal": true}}
A27: sp:fifa.friendly | B27: Football international | C27: Amicaux internationaux | D27: soccer | E27: fifa.friendly | F27: TF1 | G27: Oui | H27: Oui | L27: {"support": "ok", "def": {"id": "fifa.friendly", "region": "intl", "flag": "🌍", "sport": "soccer", "group": "foot", "name": "Amicaux internationaux", "tv": ["TF1"], "tvTeam": "France", "seasonal": true}}
A28: sp:fifa.olympics | B28: Football international | C28: Jeux olympiques | D28: soccer | E28: fifa.olympics | G28: Oui | H28: Oui | L28: {"support": "ok", "def": {"id": "fifa.olympics", "region": "intl", "flag": "🌍", "sport": "soccer", "group": "foot", "name": "Jeux olympiques", "seasonal": true}}
A29: sp:fifa.cwc | B29: Football international | C29: Coupe du monde des clubs | D29: soccer | E29: fifa.cwc | G29: Oui | H29: Oui | L29: {"support": "ok", "def": {"id": "fifa.cwc", "region": "intl", "flag": "🌍", "sport": "soccer", "group": "foot", "name": "Coupe du monde des clubs", "seasonal": true}}
A30: sp:fifa.worldq.conmebol | B30: Football international | C30: Qualifications Coupe du monde · Amérique du Sud | D30: soccer | E30: fifa.worldq.conmebol | G30: Oui | J30: à vérifier | L30: {"support": "ok", "def": {"id": "fifa.worldq.conmebol", "region": "intl", "flag": "🌍", "sport": "soccer", "group": "foot", "name": "Qualifications Coupe du monde · Amérique du Sud"}}
A31: sp:fifa.worldq.concacaf | B31: Football international | C31: Qualifications Coupe du monde · Amérique du Nord | D31: soccer | E31: fifa.worldq.concacaf | G31: Oui | J31: à vérifier | L31: {"support": "ok", "def": {"id": "fifa.worldq.concacaf", "region": "intl", "flag": "🌍", "sport": "soccer", "group": "foot", "name": "Qualifications Coupe du monde · Amérique du Nord"}}
A32: sp:fifa.worldq.caf | B32: Football international | C32: Qualifications Coupe du monde · Afrique | D32: soccer | E32: fifa.worldq.caf | G32: Oui | J32: à vérifier | L32: {"support": "ok", "def": {"id": "fifa.worldq.caf", "region": "intl", "flag": "🌍", "sport": "soccer", "group": "foot", "name": "Qualifications Coupe du monde · Afrique"}}
A33: sp:fifa.worldq.afc | B33: Football international | C33: Qualifications Coupe du monde · Asie | D33: soccer | E33: fifa.worldq.afc | G33: Oui | J33: à vérifier | L33: {"support": "ok", "def": {"id": "fifa.worldq.afc", "region": "intl", "flag": "🌍", "sport": "soccer", "group": "foot", "name": "Qualifications Coupe du monde · Asie"}}
A34: sp:uefa.euro_u21 | B34: Football international | C34: Euro Espoirs (U21) | D34: soccer | E34: uefa.euro_u21 | G34: Oui | J34: à vérifier | L34: {"support": "ok", "def": {"id": "uefa.euro_u21", "region": "intl", "flag": "🇪🇺", "sport": "soccer", "group": "foot", "name": "Euro Espoirs (U21)"}}
A35: sp:caf.nations | B35: Football international | C35: Coupe d'Afrique des nations | D35: soccer | E35: caf.nations | G35: Oui | J35: à vérifier | L35: {"support": "ok", "def": {"id": "caf.nations", "region": "intl", "flag": "🌍", "sport": "soccer", "group": "foot", "name": "Coupe d'Afrique des nations"}}
A36: sp:conmebol.america | B36: Football international | C36: Copa América | D36: soccer | E36: conmebol.america | G36: Oui | J36: à vérifier | L36: {"support": "ok", "def": {"id": "conmebol.america", "region": "intl", "flag": "🌎", "sport": "soccer", "group": "foot", "name": "Copa América"}}
A37: sp:concacaf.gold | B37: Football international | C37: Gold Cup | D37: soccer | E37: concacaf.gold | G37: Oui | J37: à vérifier | L37: {"support": "ok", "def": {"id": "concacaf.gold", "region": "intl", "flag": "🌎", "sport": "soccer", "group": "foot", "name": "Gold Cup"}}
A38: sp:afc.asian.cup | B38: Football international | C38: Coupe d'Asie des nations | D38: soccer | E38: afc.asian.cup | G38: Oui | J38: à vérifier | L38: {"support": "ok", "def": {"id": "afc.asian.cup", "region": "intl", "flag": "🌏", "sport": "soccer", "group": "foot", "name": "Coupe d'Asie des nations"}}
A39: sec:sport:en | B39: Angleterre | C39: ▸ toute la section | L39: {"id": "en", "label": "Angleterre"}
A40: sp:eng.1 | B40: Angleterre | C40: Premier League | D40: soccer | E40: eng.1 | F40: Canal+ | G40: Oui | H40: Oui | L40: {"support": "ok", "def": {"id": "eng.1", "region": "en", "flag": "🏴󠁧󠁢󠁥󠁮󠁧󠁿", "sport": "soccer", "group": "foot", "name": "Premier League", "tv": ["Canal+"], "rounds": true, "of": "en.1"}}
A41: sp:eng.2 | B41: Angleterre | C41: Championship | D41: soccer | E41: eng.2 | G41: Oui | H41: Oui | L41: {"support": "ok", "def": {"id": "eng.2", "region": "en", "flag": "🏴󠁧󠁢󠁥󠁮󠁧󠁿", "sport": "soccer", "group": "foot", "name": "Championship", "rounds": true, "of": "en.2"}}
...

Sheet Équipes favorites
A1: module=equipes;version=2 | B1: Sport · équipes favorites
B2: Les équipes cochées sont mises en avant (étoile, filtre Favoris, bandeau de l'accueil). Écris le nom tel qu'il apparaît dans les matchs (ex. « Stade Toulousain »).
B3: À remplir : cases jaunes (« Oui » ou « Non »). Ligne « ▸ toute la section » = tous ses éléments, sauf ceux marqués « Non ». Un seul élément coché suffit pour que sa section apparaisse. Colonne « Résultat » : remplie par la tâche GitHub après dépôt du classeur.
A5: ID | B5: Section | C5: Équipe | D5: Oui | E5: Résultat | F5: Note | G5: Technique
A6: sec:equipes:actuelles | B6: Mes équipes actuelles | C6: ▸ toute la section | G6: {"id": "actuelles", "label": "Mes équipes actuelles"}
A7: eq:liverpool | B7: Mes équipes actuelles | C7: Liverpool | D7: Oui | G7: {"support": "ok", "def": {"nom": "Liverpool"}}
A8: eq:arsenal | B8: Mes équipes actuelles | C8: Arsenal | D8: Oui | G8: {"support": "ok", "def": {"nom": "Arsenal"}}
A9: eq:marseille | B9: Mes équipes actuelles | C9: Marseille | D9: Oui | G9: {"support": "ok", "def": {"nom": "Marseille"}}
A10: eq:toulouse | B10: Mes équipes actuelles | C10: Toulouse | D10: Oui | G10: {"support": "ok", "def": {"nom": "Toulouse"}}
A11: eq:rodez | B11: Mes équipes actuelles | C11: Rodez | D11: Oui | G11: {"support": "ok", "def": {"nom": "Rodez"}}
A12: eq:castres | B12: Mes équipes actuelles | C12: Castres | D12: Oui | G12: {"support": "ok", "def": {"nom": "Castres"}}
A13: eq:stade-toulousain | B13: Mes équipes actuelles | C13: Stade Toulousain | D13: Oui | G13: {"support": "ok", "def": {"nom": "Stade Toulousain"}}
A14: eq:lakers | B14: Mes équipes actuelles | C14: Lakers | D14: Oui | G14: {"support": "ok", "def": {"nom": "Lakers"}}
A15: eq:packers | B15: Mes équipes actuelles | C15: Packers | D15: Oui | G15: {"support": "ok", "def": {"nom": "Packers"}}
A16: eq:steelers | B16: Mes équipes actuelles | C16: Steelers | D16: Oui | G16: {"support": "ok", "def": {"nom": "Steelers"}}
A17: eq:maple-leafs | B17: Mes équipes actuelles | C17: Maple Leafs | D17: Oui | G17: {"support": "ok", "def": {"nom": "Maple Leafs"}}
A18: sec:equipes:foot-france | B18: Foot · France | C18: ▸ toute la section | G18: {"id": "foot-france", "label": "Foot · France"}
A19: eq:paris-sg | B19: Foot · France | C19: Paris SG | G19: {"support": "ok", "def": {"nom": "Paris SG"}}
A20: eq:lyon | B20: Foot · France | C20: Lyon | G20: {"support": "ok", "def": {"nom": "Lyon"}}
A21: eq:lens | B21: Foot · France | C21: Lens | G21: {"support": "ok", "def": {"nom": "Lens"}}
A22: eq:lille | B22: Foot · France | C22: Lille | G22: {"support": "ok", "def": {"nom": "Lille"}}
A23: eq:monaco | B23: Foot · France | C23: Monaco | D23: Oui | G23: {"support": "ok", "def": {"nom": "Monaco"}}
A24: eq:nice | B24: Foot · France | C24: Nice | G24: {"support": "ok", "def": {"nom": "Nice"}}
A25: eq:rennes | B25: Foot · France | C25: Rennes | G25: {"support": "ok", "def": {"nom": "Rennes"}}
A26: eq:nantes | B26: Foot · France | C26: Nantes | G26: {"support": "ok", "def": {"nom": "Nantes"}}
A27: eq:strasbourg | B27: Foot · France | C27: Strasbourg | G27: {"support": "ok", "def": {"nom": "Strasbourg"}}
A28: eq:montpellier | B28: Foot · France | C28: Montpellier | G28: {"support": "ok", "def": {"nom": "Montpellier"}}
A29: eq:saint-etienne | B29: Foot · France | C29: Saint-Étienne | G29: {"support": "ok", "def": {"nom": "Saint-Étienne"}}
A30: eq:bordeaux | B30: Foot · France | C30: Bordeaux | G30: {"support": "ok", "def": {"nom": "Bordeaux"}}
A31: sec:equipes:foot-europe | B31: Foot · Europe | C31: ▸ toute la section | G31: {"id": "foot-europe", "label": "Foot · Europe"}
A32: eq:real-madrid | B32: Foot · Europe | C32: Real Madrid | G32: {"support": "ok", "def": {"nom": "Real Madrid"}}
A33: eq:fc-barcelone | B33: Foot · Europe | C33: FC Barcelone | G33: {"support": "ok", "def": {"nom": "FC Barcelone"}}
A34: eq:bayern-munich | B34: Foot · Europe | C34: Bayern Munich | G34: {"support": "ok", "def": {"nom": "Bayern Munich"}}
A35: eq:manchester-city | B35: Foot · Europe | C35: Manchester City | G35: {"support": "ok", "def": {"nom": "Manchester City"}}
... A65: eq:yankees | B65: US | C65: Yankees | G65: {"support": "ok", "def": {"nom": "Yankees"}}
B68: MES AJOUTS — tape ce que tu veux ajouter : la tâche essaie de le récupérer et écrit le résultat (✅ / ⚠️ / ❌) dans la colonne « Résultat »
B69: Catégorie | C69: Nom de l'équipe | D69: Oui | E69: Résultat | F69: Note
A70: exemple | B70: Mes équipes actuelles | C70: Montpellier HSC | D70: Oui | F70: Ligne d'exemple : ignorée par la tâche
A71: ajout:1
A72: ajout:2
...

Sheet Actus
A1: module=actus;version=2 | B1: Actus · rubriques et médias (français)
B2: Une rubrique = un onglet de la page Actus. Coche un média : sa rubrique apparaît avec lui. Coche la ligne « toute la rubrique » pour prendre tous ses médias (et mets « Non » sur ceux que tu ne veux pas). Les flux « Google » suivent un mot-clé plutôt qu'un site.
B3: À remplir : cases jaunes (« Oui » ou « Non »). Ligne « ▸ toute la section » = tous ses éléments, sauf ceux marqués « Non ». Un seul élément coché suffit pour que sa section apparaisse. Colonne « Résultat » : remplie par la tâche GitHub après dépôt du classeur.
A5: ID | B5: Section | C5: Média | D5: Adresse du flux | E5: Site (secours) | F5: Oui | G5: Résultat | H5: Note | I5: Technique
A6: sec:actus:une | B6: À la une | C6: ▸ toute la section | I6: {"id": "une", "label": "À la une", "liste": "principal"}
A7: actus:une:france-info | B7: À la une | C7: France Info | D7: https://www.francetvinfo.fr/titres.rss | F7: Oui | I7: {"support": "ok", "def": {"name": "France Info", "color": "#f2b705", "url": "https://www.francetvinfo.fr/titres.rss"}}
A8: actus:une:le-monde | B8: À la une | C8: Le Monde | D8: https://www.lemonde.fr/rss/une.xml | F8: Oui | I8: {"support": "ok", "def": {"name": "Le Monde", "color": "#2b2b2b", "url": "https://www.lemonde.fr/rss/une.xml"}}
A9: actus:une:le-figaro | B9: À la une | C9: Le Figaro | D9: https://www.lefigaro.fr/rss/figaro_actualites.xml | F9: Oui | I9: {"support": "ok", "def": {"name": "Le Figaro", "color": "#163860", "url": "https://www.lefigaro.fr/rss/figaro_actualites.xml"}}
A10: actus:une:liberation | B10: À la une | C10: Libération | D10: https://www.liberation.fr/arc/outboundfeeds/rss-all/?outputType=xml | F10: Oui | I10: {"support": "ok", "def": {"name": "Libération", "color": "#e2001a", "url": "https://www.liberation.fr/arc/outboundfeeds/rss-all/?outputType=xml"}}
A11: actus:une:20-minutes | B11: À la une | C11: 20 Minutes | D11: https://www.20minutes.fr/feeds/rss-une.xml | F11: Oui | I11: {"support": "ok", "def": {"name": "20 Minutes", "color": "#0b5fb4", "url": "https://www.20minutes.fr/feeds/rss-une.xml"}}
A12: actus:une:ouest-france | B12: À la une | C12: Ouest-France | D12: https://www.ouest-france.fr/rss/une | E12: https://www.ouest-france.fr/ | G12: à vérifier | I12: {"support": "ok", "def": {"name": "Ouest-France", "color": "#e2001a", "url": "https://www.ouest-france.fr/rss/une", "site": "https://www.ouest-france.fr/", "alt": ["https://news.google.com/rss/search?q=site:ouest-france.fr&hl=fr&gl=FR&ceid=FR:fr"]}}
A13: actus:une:le-parisien | B13: À la une | C13: Le Parisien | D13: https://feeds.leparisien.fr/leparisien/rss | E13: https://www.leparisien.fr/ | G13: à vérifier | I13: {"support": "ok", "def": {"name": "Le Parisien", "color": "#1a4c8b", "url": "https://feeds.leparisien.fr/leparisien/rss", "site": "https://www.leparisien.fr/", "alt": ["https://news.google.com/rss/search?q=site:leparisien.fr&hl=fr&gl=FR&ceid=FR:fr"]}}
A14: actus:une:le-point | B14: À la une | C14: Le Point | D14: https://www.lepoint.fr/rss.xml | E14: https://www.lepoint.fr/ | G14: à vérifier | I14: {"support": "ok", "def": {"name": "Le Point", "color": "#c8102e", "url": "https://www.lepoint.fr/rss.xml", "site": "https://www.lepoint.fr/", "alt": ["https://news.google.com/rss/search?q=site:lepoint.fr&hl=fr&gl=FR&ceid=FR:fr"]}}
A15: actus:une:l-express | B15: À la une | C15: L'Express | D15: https://www.lexpress.fr/arc/outboundfeeds/rss/alaune.xml | E15: https://www.lexpress.fr/ | G15: à vérifier | I15: {"support": "ok", "def": {"name": "L'Express", "color": "#e2001a", "url": "https://www.lexpress.fr/arc/outboundfeeds/rss/alaune.xml", "site": "https://www.lexpress.fr/", "alt": ["https://news.google.com/rss/search?q=site:lexpress.fr&hl=fr&gl=FR&ceid=FR:fr"]}}
A16: actus:une:la-croix | B16: À la une | C16: La Croix | D16: https://www.la-croix.com/RSS/UNIVERS | E16: https://www.la-croix.com/ | G16: à vérifier | I16: {"support": "ok", "def": {"name": "La Croix", "color": "#1f3f75", "url": "https://www.la-croix.com/RSS/UNIVERS", "site": "https://www.la-croix.com/", "alt": ["https://news.google.com/rss/search?q=site:la-croix.com&hl=fr&gl=FR&ceid=FR:fr"]}}
A17: actus:une:huffpost | B17: À la une | C17: HuffPost | D17: https://www.huffingtonpost.fr/feeds/index.xml | E17: https://www.huffingtonpost.fr/ | G17: à vérifier | I17: {"support": "ok", "def": {"name": "HuffPost", "color": "#0dbe98", "url": "https://www.huffingtonpost.fr/feeds/index.xml", "site": "https://www.huffingtonpost.fr/", "alt": ["https://news.google.com/rss/search?q=site:huffingtonpost.fr&hl=fr&gl=FR&ceid=FR:fr"]}}
A18: actus:une:bfmtv | B18: À la une | C18: BFMTV | D18: https://www.bfmtv.com/rss/news-24-7/ | E18: https://www.bfmtv.com/ | G18: à vérifier | I18: {"support": "ok", "def": {"name": "BFMTV", "color": "#0a2c5a", "url": "https://www.bfmtv.com/rss/news-24-7/", "site": "https://www.bfmtv.com/", "alt": ["https://news.google.com/rss/search?q=site:bfmtv.com&hl=fr&gl=FR&ceid=FR:fr"]}}
A19: actus:une:tf1-info | B19: À la une | C19: TF1 Info | D19: https://www.tf1info.fr/feeds/rss-une.xml | E19: https://www.tf1info.fr/ | G19: à vérifier | I19: {"support": "ok", "def": {"name": "TF1 Info", "color": "#0067b1", "url": "https://www.tf1info.fr/feeds/rss-une.xml", "site": "https://www.tf1info.fr/", "alt": ["https://news.google.com/rss/search?q=site:tf1info.fr&hl=fr&gl=FR&ceid=FR:fr"]}}
A20: actus:une:france-24 | B20: À la une | C20: France 24 | D20: https://www.france24.com/fr/rss | E20: https://www.france24.com/fr/ | G20: à vérifier | I20: {"support": "ok", "def": {"name": "France 24", "color": "#00a3e0", "url": "https://www.france24.com/fr/rss", "site": "https://www.france24.com/fr/", "alt": ["https://news.google.com/rss/search?q=site:france24.com&hl=fr&gl=FR&ceid=FR:fr"]}}
A21: actus:une:rfi | B21: À la une | C21: RFI | D21: https://www.rfi.fr/fr/rss | E21: https://www.rfi.fr/fr/ | G21: à vérifier | I21: {"support": "ok", "def": {"name": "RFI", "color": "#e5004d", "url": "https://www.rfi.fr/fr/rss", "site": "https://www.rfi.fr/fr/", "alt": ["https://news.google.com/rss/search?q=site:rfi.fr&hl=fr&gl=FR&ceid=FR:fr"]}}
A22: actus:une:mediapart | B22: À la une | C22: Mediapart | D22: https://www.mediapart.fr/articles/feed | E22: https://www.mediapart.fr/ | G22: à vérifier | I22: {"support": "ok", "def": {"name": "Mediapart", "color": "#e5004c", "url": "https://www.mediapart.fr/articles/feed", "site": "https://www.mediapart.fr/", "alt": ["https://news.google.com/rss/search?q=site:mediapart.fr&hl=fr&gl=FR&ceid=FR:fr"]}}
A23: actus:une:l-humanite | B23: À la une | C23: L'Humanité | D23: https://www.humanite.fr/feed | E23: https://www.humanite.fr/ | G23: à vérifier | I23: {"support": "ok", "def": {"name": "L'Humanité", "color": "#d30000", "url": "https://www.humanite.fr/feed", "site": "https://www.humanite.fr/", "alt": ["https://news.google.com/rss/search?q=site:humanite.fr&hl=fr&gl=FR&ceid=FR:fr"]}}
... A25: actus:une:europe-1 | B25: À la une | C25: Europe 1 | D25: https://www.europe1.fr/rss.xml | E25: https://www.europe1.fr/ | G25: à vérifier | I25: {"support": "ok", "def": {"name": "Europe 1", "color": "#e30613", "url": "https://www.europe1.fr/rss.xml", "site": "https://www.europe1.fr/", "alt": ["https://news.google.com/rss/search?q=site:europe1.fr&hl=fr&gl=FR&ceid=FR:fr"]}}
A26: sec:actus:france | B26: France | C26: ▸ toute la section | I26: {"id": "france", "label": "France", "liste": "principal"}
A27: actus:france:france-info | B27: France | C27: France Info | D27: https://www.francetvinfo.fr/france.rss | F27: Oui | I27: {"support": "ok", "def": {"name": "France Info", "color": "#f2b705", "url": "https://www.francetvinfo.fr/france.rss"}}
A28: actus:france:le-monde | B28: France | C28: Le Monde | D28: https://www.lemonde.fr/politique/rss_full.xml | F28: Oui | I28: {"support": "ok", "def": {"name": "Le Monde", "color": "#2b2b2b", "url": "https://www.lemonde.fr/politique/rss_full.xml"}}
A29: actus:france:le-figaro | B29: France | C29: Le Figaro | D29: https://www.lefigaro.fr/rss/figaro_politique.xml | F29: Oui | I29: {"support": "ok", "def": {"name": "Le Figaro", "color": "#163860", "url": "https://www.lefigaro.fr/rss/figaro_politique.xml"}}
A30: actus:france:public-senat | B30: France | C30: Public Sénat | D30: https://www.publicsenat.fr/rss.xml | E30: https://www.publicsenat.fr/ | G30: à vérifier | I30: {"support": "ok", "def": {"name": "Public Sénat", "color": "#c8102e", "url": "https://www.publicsenat.fr/rss.xml", "site": "https://www.publicsenat.fr/", "alt": ["https://news.google.com/rss/search?q=site:publicsenat.fr&hl=fr&gl=FR&ceid=FR:fr"]}}
A31: actus:france:lcp | B31: France | C31: LCP | D31: https://lcp.fr/rss.xml | E31: https://lcp.fr/ | G31: à vérifier | I31: {"support": "ok", "def": {"name": "LCP", "color": "#003c71", "url": "https://lcp.fr/rss.xml", "site": "https://lcp.fr/", "alt": ["https://news.google.com/rss/search?q=site:lcp.fr&hl=fr&gl=FR&ceid=FR:fr"]}}
A32: actus:france:france-info-politique | B32: France | C32: France Info · Politique | D32: https://www.francetvinfo.fr/politique.rss | G32: à vérifier | I32: {"support": "ok", "def": {"name": "France Info · Politique", "color": "#f2b705", "url": "https://www.francetvinfo.fr/politique.rss", "alt": ["https://news.google.com/rss/search?q=site:francetvinfo.fr&hl=fr&gl=FR&ceid=FR:fr"]}}
A33: actus:france:vie-publique-fr | B33: France | C33: Vie-publique.fr | D33: https://www.vie-publique.fr/actualites.xml | E33: https://www.vie-publique.fr/ | G33: à vérifier | I33: {"support": "ok", "def": {"name": "Vie-publique.fr", "color": "#000091", "url": "https://www.vie-publique.fr/actualites.xml", "site": "https://www.vie-publique.fr/", "alt": ["https://news.google.com/rss/search?q=site:vie-publique.fr&hl=fr&gl=FR&ceid=FR:fr"]}}
A34: sec:actus:monde | B34: Monde | C34: ▸ toute la section | I34: {"id": "monde", "label": "Monde", "liste": "principal"}
A35: actus:monde:france-info | B35: Monde | C35: France Info | D35: https://www.francetvinfo.fr/monde.rss | F35: Oui | I35: {"support": "ok", "def": {"name": "France Info", "color": "#f2b705", "url": "https://www.francetvinfo.fr/monde.rss"}}
A36: actus:monde:le-monde | B36: Monde | C36: Le Monde | D36: https://www.lemonde.fr/international/rss_full.xml | F36: Oui | I36: {"support": "ok", "def": {"name": "Le Monde", "color": "#2b2b2b", "url": "https://www.lemonde.fr/international/rss_full.xml"}}
A37: actus:monde:courrier-international | B37: Monde | C37: Courrier international | D37: https://www.courrierinternational.com/feed/all/rss.xml | F37: Oui | I37: {"support": "ok", "def": {"name": "Courrier international", "color": "#c8102e", "url": "https://www.courrierinternational.com/feed/all/rss.xml"}}
A38: actus:monde:france-24-monde | B38: Monde | C38: France 24 · Monde | D38: https://www.france24.com/fr/monde/rss | E38: https://www.france24.com/fr/ | G38: à vérifier | I38: {"support": "ok", "def": {"name": "France 24 · Monde", "color": "#00a3e0", "url": "https://www.france24.com/fr/monde/rss", "site": "https://www.france24.com/fr/", "alt": ["https://news.google.com/rss/search?q=site:france24.com&hl=fr&gl=FR&ceid=FR:fr"]}}
A39: actus:monde:rfi-monde | B39: Monde | C39: RFI · Monde | D39: https://www.rfi.fr/fr/monde/rss | E39: https://www.rfi.fr/fr/ | G39: à vérifier | I39: {"support": "ok", "def": {"name": "RFI · Monde", "color": "#e5004d", "url": "https://www.rfi.fr/fr/monde/rss", "site": "https://www.rfi.fr/fr/", "alt": ["https://news.google.com/rss/search?q=site:rfi.fr&hl=fr&gl=FR&ceid=FR:fr"]}}
A40: actus:monde:le-grand-continent | B40: Monde | C40: Le Grand Continent | D40: https://legrandcontinent.eu/fr/feed/ | E40: https://legrandcontinent.eu/fr/ | G40: à vérifier | I40: {"support": "ok", "def": {"name": "Le Grand Continent", "color": "#111111", "url": "https://legrandcontinent.eu/fr/feed/", "site": "https://legrandcontinent.eu/fr/", "alt": ["https://news.google.com/rss/search?q=site:legrandcontinent.eu&hl=fr&gl=FR&ceid=FR:fr"]}}
A41: actus:monde:le-monde-diplomatique | B41: Monde | C41: Le Monde diplomatique | D41: https://www.monde-diplomatique.fr/rss/ | E41: https://www.monde-diplomatique.fr/ | G41: à vérifier | I41: {"support": "ok", "def": {"name": "Le Monde diplomatique", "color": "#5a0f0f", "url": "https://www.monde-diplomatique.fr/rss/", "site": "https://www.monde-diplomatique.fr/", "alt": ["https://news.google.com/rss/search?q=site:monde-diplomatique.fr&hl=fr&gl=FR&ceid=FR:fr"]}}
A42: actus:monde:tv5monde-info | B42: Monde | C42: TV5Monde Info | D42: https://information.tv5monde.com/rss.xml | E42: https://information.tv5monde.com/ | G42: à vérifier | I42: {"support": "ok", "def": {"name": "TV5Monde Info", "color": "#2a2a7a", "url": "https://information.tv5monde.com/rss.xml", "site": "https://information.tv5monde.com/", "alt": ["https://news.google.com/rss/search?q=site:information.tv5monde.com&hl=fr&gl=FR&ceid=FR:fr"]}}
...

Sheet Actus International
A1: module=actus-en;version=2 | B1: Actus · mode International (anglais)
B2: Mêmes rubriques, médias anglophones : affichés quand tu touches la bulle 🇺🇸 de la page Actus.
B3: À remplir : cases jaunes (« Oui » ou « Non »). Ligne « ▸ toute la section » = tous ses éléments, sauf ceux marqués « Non ». Un seul élément coché suffit pour que sa section apparaisse. Colonne « Résultat » : remplie par la tâche GitHub après dépôt du classeur.
A5: ID | B5: Section | C5: Média | D5: Adresse du flux | E5: Site (secours) | F5: Oui | G5: Résultat | H5: Note | I5: Technique
A6: sec:actus-en:une | B6: À la une | C6: ▸ toute la section | I6: {"id": "une", "label": "À la une", "liste": "principal"}
A7: actus-en:une:bbc-news | B7: À la une | C7: BBC News | D7: https://feeds.bbci.co.uk/news/rss.xml | F7: Oui | I7: {"support": "ok", "def": {"name": "BBC News", "color": "#bb1919", "url": "https://feeds.bbci.co.uk/news/rss.xml"}}
A8: actus-en:une:sky-news | B8: À la une | C8: Sky News | D8: https://feeds.skynews.com/feeds/rss/home.xml | F8: Oui | I8: {"support": "ok", "def": {"name": "Sky News", "color": "#c4122f", "url": "https://feeds.skynews.com/feeds/rss/home.xml"}}
A9: actus-en:une:euronews | B9: À la une | C9: Euronews | D9: https://www.euronews.com/rss?format=mrss&level=theme&name=news | F9: Oui | I9: {"support": "ok", "def": {"name": "Euronews", "color": "#0b3c8c", "url": "https://www.euronews.com/rss?format=mrss&level=theme&name=news"}}
A10: actus-en:une:the-guardian | B10: À la une | C10: The Guardian | D10: https://www.theguardian.com/international/rss | F10: Oui | I10: {"support": "ok", "def": {"name": "The Guardian", "color": "#052962", "url": "https://www.theguardian.com/international/rss"}}
A11: actus-en:une:new-york-times | B11: À la une | C11: New York Times | D11: https://rss.nytimes.com/services/xml/rss/nyt/HomePage.xml | F11: Oui | I11: {"support": "ok", "def": {"name": "New York Times", "color": "#2b2b2b", "url": "https://rss.nytimes.com/services/xml/rss/nyt/HomePage.xml"}}
A12: actus-en:une:wall-street-journal | B12: À la une | C12: Wall Street Journal | D12: https://feeds.content.dowjones.io/public/rss/RSSWorldNews | F12: Oui | I12: {"support": "ok", "def": {"name": "Wall Street Journal", "color": "#0274b6", "url": "https://feeds.content.dowjones.io/public/rss/RSSWorldNews", "alt": ["https://news.google.com/rss/search?q=site:wsj.com&hl=en-US&gl=US&ceid=US:en"]}}
A13: actus-en:une:npr | B13: À la une | C13: NPR | D13: https://feeds.npr.org/1001/rss.xml | E13: https://www.npr.org/ | G13: à vérifier | I13: {"support": "ok", "def": {"name": "NPR", "color": "#2b2b2b", "url": "https://feeds.npr.org/1001/rss.xml", "site": "https://www.npr.org/", "alt": ["https://news.google.com/rss/search?q=site:npr.org&hl=en-US&gl=US&ceid=US:en"]}}
A14: actus-en:une:reuters-google | B14: À la une | C14: Reuters (Google) | D14: https://news.google.com/rss/search?q=site:reuters.com&hl=en-US&gl=US&ceid=US:en | G14: à vérifier | H14: Flux Google Actualités (mot-clé) | I14: {"support": "ok", "def": {"name": "Reuters (Google)", "color": "#ff8000", "url": "https://news.google.com/rss/search?q=site:reuters.com&hl=en-US&gl=US&ceid=US:en"}}
A15: actus-en:une:associated-press-google | B15: À la une | C15: Associated Press (Google) | D15: https://news.google.com/rss/search?q=site:apnews.com&hl=en-US&gl=US&ceid=US:en | G15: à vérifier | H15: Flux Google Actualités (mot-clé) | I15: {"support": "ok", "def": {"name": "Associated Press (Google)", "color": "#e2001a", "url": "https://news.google.com/rss/search?q=site:apnews.com&hl=en-US&gl=US&ceid=US:en"}}
A16: actus-en:une:cnn | B16: À la une | C16: CNN | D16: http://rss.cnn.com/rss/edition.rss | E16: https://edition.cnn.com/ | G16: à vérifier | I16: {"support": "ok", "def": {"name": "CNN", "color": "#cc0000", "url": "http://rss.cnn.com/rss/edition.rss", "site": "https://edition.cnn.com/", "alt": ["https://news.google.com/rss/search?q=site:edition.cnn.com&hl=en-US&gl=US&ceid=US:en"]}}
A17: actus-en:une:washington-post | B17: À la une | C17: Washington Post | D17: https://feeds.washingtonpost.com/rss/world | E17: https://www.washingtonpost.com/ | G17: à vérifier | I17: {"support": "ok", "def": {"name": "Washington Post", "color": "#111111", "url": "https://feeds.washingtonpost.com/rss/world", "site": "https://www.washingtonpost.com/", "alt": ["https://news.google.com/rss/search?q=site:washingtonpost.com&hl=en-US&gl=US&ceid=US:en"]}}
A18: actus-en:une:the-independent | B18: À la une | C18: The Independent | D18: https://www.independent.co.uk/news/rss | E18: https://www.independent.co.uk/ | G18: à vérifier | I18: {"support": "ok", "def": {"name": "The Independent", "color": "#e2001a", "url": "https://www.independent.co.uk/news/rss", "site": "https://www.independent.co.uk/", "alt": ["https://news.google.com/rss/search?q=site:independent.co.uk&hl=en-US&gl=US&ceid=US:en"]}}
A19: sec:actus-en:france | B19: France | C19: ▸ toute la section | I19: {"id": "france", "label": "France", "liste": "principal"}
A20: actus-en:france:france-24 | B20: France | C20: France 24 | D20: https://www.france24.com/en/france/rss | F20: Oui | I20: {"support": "ok", "def": {"name": "France 24", "color": "#00a3e0", "url": "https://www.france24.com/en/france/rss"}}
A21: actus-en:france:rfi | B21: France | C21: RFI | D21: https://www.rfi.fr/en/france/rss | F21: Oui | I21: {"support": "ok", "def": {"name": "RFI", "color": "#e5004d", "url": "https://www.rfi.fr/en/france/rss", "alt": ["https://news.google.com/rss/search?q=site:rfi.fr/en&hl=en-US&gl=US&ceid=US:en"]}}
A22: actus-en:france:the-local | B22: France | C22: The Local | D22: https://www.thelocal.fr/feeds/rss.php | E22: https://www.thelocal.fr/ | F22: Oui | I22: {"support": "ok", "def": {"name": "The Local", "color": "#e2001a", "url": "https://www.thelocal.fr/feeds/rss.php", "site": "https://www.thelocal.fr/", "alt": ["https://news.google.com/rss/search?q=site:thelocal.fr&hl=en-US&gl=US&ceid=US:en"]}}
A23: sec:actus-en:monde | B23: Monde | C23: ▸ toute la section | I23: {"id": "monde", "label": "Monde", "liste": "principal"}
A24: actus-en:monde:bbc-news | B24: Monde | C24: BBC News | D24: https://feeds.bbci.co.uk/news/world/rss.xml | F24: Oui | I24: {"support": "ok", "def": {"name": "BBC News", "color": "#bb1919", "url": "https://feeds.bbci.co.uk/news/world/rss.xml"}}
A25: actus-en:monde:the-guardian | B25: Monde | C25: The Guardian | D25: https://www.theguardian.com/world/rss | F25: Oui | I25: {"support": "ok", "def": {"name": "The Guardian", "color": "#052962", "url": "https://www.theguardian.com/world/rss"}}
A26: actus-en:monde:new-york-times | B26: Monde | C26: New York Times | D26: https://rss.nytimes.com/services/xml/rss/nyt/World.xml | F26: Oui | I26: {"support": "ok", "def": {"name": "New York Times", "color": "#2b2b2b", "url": "https://rss.nytimes.com/services/xml/rss/nyt/World.xml"}}
A27: actus-en:monde:sky-news | B27: Monde | C27: Sky News | D27: https://feeds.skynews.com/feeds/rss/world.xml | F27: Oui | I27: {"support": "ok", "def": {"name": "Sky News", "color": "#c4122f", "url": "https://feeds.skynews.com/feeds/rss/world.xml"}}
A28: actus-en:monde:wall-street-journal | B28: Monde | C28: Wall Street Journal | D28: https://feeds.content.dowjones.io/public/rss/RSSWorldNews | F28: Oui | I28: {"support": "ok", "def": {"name": "Wall Street Journal", "color": "#0274b6", "url": "https://feeds.content.dowjones.io/public/rss/RSSWorldNews"}}
A29: actus-en:monde:al-jazeera | B29: Monde | C29: Al Jazeera | D29: https://www.aljazeera.com/xml/rss/all.xml | F29: Oui | I29: {"support": "ok", "def": {"name": "Al Jazeera", "color": "#d39c1f", "url": "https://www.aljazeera.com/xml/rss/all.xml"}}
A30: actus-en:monde:deutsche-welle | B30: Monde | C30: Deutsche Welle | D30: https://rss.dw.com/rdf/rss-en-all | E30: https://www.dw.com/en/ | G30: à vérifier | I30: {"support": "ok", "def": {"name": "Deutsche Welle", "color": "#0c4da2", "url": "https://rss.dw.com/rdf/rss-en-all", "site": "https://www.dw.com/en/", "alt": ["https://news.google.com/rss/search?q=site:dw.com&hl=en-US&gl=US&ceid=US:en"]}}
A31: actus-en:monde:politico-europe | B31: Monde | C31: Politico Europe | D31: https://www.politico.eu/feed/ | E31: https://www.politico.eu/ | G31: à vérifier | I31: {"support": "ok", "def": {"name": "Politico Europe", "color": "#d6001c", "url": "https://www.politico.eu/feed/", "site": "https://www.politico.eu/", "alt": ["https://news.google.com/rss/search?q=site:politico.eu&hl=en-US&gl=US&ceid=US:en"]}}
A32: actus-en:monde:foreign-policy | B32: Monde | C32: Foreign Policy | D32: https://foreignpolicy.com/feed/ | E32: https://foreignpolicy.com/ | G32: à vérifier | I32: {"support": "ok", "def": {"name": "Foreign Policy", "color": "#111111", "url": "https://foreignpolicy.com/feed/", "site": "https://foreignpolicy.com/", "alt": ["https://news.google.com/rss/search?q=site:foreignpolicy.com&hl=en-US&gl=US&ceid=US:en"]}}
A33: actus-en:monde:the-atlantic | B33: Monde | C33: The Atlantic | D33: https://www.theatlantic.com/feed/all/ | E33: https://www.theatlantic.com/ | G33: à vérifier | I33: {"support": "ok", "def": {"name": "The Atlantic", "color": "#111111", "url": "https://www.theatlantic.com/feed/all/", "site": "https://www.theatlantic.com/", "alt": ["https://news.google.com/rss/search?q=site:theatlantic.com&hl=en-US&gl=US&ceid=US:en"]}}
A34: sec:actus-en:eco | B34: Éco | C34: ▸ toute la section | I34: {"id": "eco", "label": "Éco", "liste": "principal"}
A35: actus-en:eco:financial-times | B35: Éco | C35: Financial Times | D35: https://www.ft.com/rss/home | F35: Oui | I35: {"support": "ok", "def": {"name": "Financial Times", "color": "#990f3d", "url": "https://www.ft.com/rss/home", "alt": ["https://news.google.com/rss/search?q=site:ft.com&hl=en-US&gl=US&ceid=US:en"]}}
A36: actus-en:eco:the-economist | B36: Éco | C36: The Economist | D36: https://www.economist.com/finance-and-economics/rss.xml | F36: Oui | I36: {"support": "ok", "def": {"name": "The Economist", "color": "#e3120b", "url": "https://www.economist.com/finance-and-economics/rss.xml", "alt": ["https://news.google.com/rss/search?q=site:economist.com&hl=en-US&gl=US&ceid=US:en"]}}
A37: actus-en:eco:wall-street-journal | B37: Éco | C37: Wall Street Journal | D37: https://feeds.content.dowjones.io/public/rss/RSSMarketsMain | F37: Oui | I37: {"support": "ok", "def": {"name": "Wall Street Journal", "color": "#0274b6", "url": "https://feeds.content.dowjones.io/public/rss/RSSMarketsMain", "alt": ["https://news.google.com/rss/search?q=site:wsj.com&hl=en-US&gl=US&ceid=US:en"]}}
A38: actus-en:eco:bbc-news | B38: Éco | C38: BBC News | D38: https://feeds.bbci.co.uk/news/business/rss.xml | F38: Oui | I38: {"support": "ok", "def": {"name": "BBC News", "color": "#bb1919", "url": "https://feeds.bbci.co.uk/news/business/rss.xml"}}
A39: actus-en:eco:cnbc | B39: Éco | C39: CNBC | D39: https://www.cnbc.com/id/100003114/device/rss/rss.html | E39: https://www.cnbc.com/ | G39: à vérifier | I39: {"support": "ok", "def": {"name": "CNBC", "color": "#005594", "url": "https://www.cnbc.com/id/100003114/device/rss/rss.html", "site": "https://www.cnbc.com/", "alt": ["https://news.google.com/rss/search?q=site:cnbc.com&hl=en-US&gl=US&ceid=US:en"]}}
A40: actus-en:eco:bloomberg-google | B40: Éco | C40: Bloomberg (Google) | D40: https://news.google.com/rss/search?q=site:bloomberg.com&hl=en-US&gl=US&ceid=US:en | G40: à vérifier | H40: Flux Google Actualités (mot-clé) | I40: {"support": "ok", "def": {"name": "Bloomberg (Google)", "color": "#111111", "url": "https://news.google.com/rss/search?q=site:bloomberg.com&hl=en-US&gl=US&ceid=US:en"}}
A41: actus-en:eco:marketwatch | B41: Éco | C41: MarketWatch | D41: https://feeds.content.dowjones.io/public/rss/mw_topstories | E41: https://www.marketwatch.com/ | G41: à vérifier | I41: {"support": "ok", "def": {"name": "MarketWatch", "color": "#0a7a3b", "url": "https://feeds.content.dowjones.io/public/rss/mw_topstories", "site": "https://www.marketwatch.com/", "alt": ["https://news.google.com/rss/search?q=site:marketwatch.com&hl=en-US&gl=US&ceid=US:en"]}}
...

Sheet Marchés
A1: module=marches;version=2 | B1: Investissements · marchés et fonds suivis
B2: Indices, devises, matières premières, taux, cryptos et fonds affichés dans la page Investissements. « Widget accueil » : affiché aussi sur l'écran d'accueil. Pour tes fonds, l'ISIN suffit (jamais de quantités ni de montants ici : le dépôt est public).
B3: À remplir : cases jaunes (« Oui » ou « Non »). Ligne « ▸ toute la section » = tous ses éléments, sauf ceux marqués « Non ». Un seul élément coché suffit pour que sa section apparaisse. Colonne « Résultat » : remplie par la tâche GitHub après dépôt du classeur.
A5: ID | B5: Section | C5: Nom | D5: Code de cotation | E5: ISIN | F5: Précision | G5: Oui | H5: Widget accueil | I5: Résultat | J5: Note | K5: Technique
A6: sec:marches:idx_eu | B6: Indices · Europe | C6: ▸ toute la section | K6: {"id": "idx_eu", "label": "Indices · Europe", "liste": "indices"}
A7: mk:cac40 | B7: Indices · Europe | C7: CAC 40 | D7: ^FCHI | G7: Oui | H7: Oui | K7: {"support": "ok", "def": {"id": "cac40", "code": "^FCHI", "nom": "CAC 40"}}
A8: mk:eurostoxx50 | B8: Indices · Europe | C8: Euro Stoxx 50 | D8: ^STOXX50E | G8: Oui | K8: {"support": "ok", "def": {"id": "eurostoxx50", "code": "^STOXX50E", "nom": "Euro Stoxx 50"}}
A9: mk:sbf120 | B9: Indices · Europe | C9: SBF 120 | D9: ^SBF120 | I9: à vérifier | K9: {"support": "ok", "def": {"id": "sbf120", "code": "^SBF120", "nom": "SBF 120"}}
A10: mk:stoxx600 | B10: Indices · Europe | C10: Stoxx Europe 600 | D10: ^STOXX | I10: à vérifier | K10: {"support": "ok", "def": {"id": "stoxx600", "code": "^STOXX", "nom": "Stoxx Europe 600"}}
A11: mk:dax | B11: Indices · Europe | C11: DAX (Allemagne) | D11: ^GDAXI | I11: à vérifier | K11: {"support": "ok", "def": {"id": "dax", "code": "^GDAXI", "nom": "DAX (Allemagne)"}}
A12: mk:ftse100 | B12: Indices · Europe | C12: FTSE 100 (Royaume-Uni) | D12: ^FTSE | I12: à vérifier | K12: {"support": "ok", "def": {"id": "ftse100", "code": "^FTSE", "nom": "FTSE 100 (Royaume-Uni)"}}
A13: mk:ibex35 | B13: Indices · Europe | C13: IBEX 35 (Espagne) | D13: ^IBEX | I13: à vérifier | K13: {"support": "ok", "def": {"id": "ibex35", "code": "^IBEX", "nom": "IBEX 35 (Espagne)"}}
A14: mk:ftsemib | B14: Indices · Europe | C14: FTSE MIB (Italie) | D14: FTSEMIB.MI | I14: à vérifier | K14: {"support": "ok", "def": {"id": "ftsemib", "code": "FTSEMIB.MI", "nom": "FTSE MIB (Italie)"}}
A15: mk:aex | B15: Indices · Europe | C15: AEX (Pays-Bas) | D15: ^AEX | I15: à vérifier | K15: {"support": "ok", "def": {"id": "aex", "code": "^AEX", "nom": "AEX (Pays-Bas)"}}
A16: mk:smi | B16: Indices · Europe | C16: SMI (Suisse) | D16: ^SSMI | I16: à vérifier | K16: {"support": "ok", "def": {"id": "smi", "code": "^SSMI", "nom": "SMI (Suisse)"}}
A17: mk:bel20 | B17: Indices · Europe | C17: BEL 20 (Belgique) | D17: ^BFX | I17: à vérifier | K17: {"support": "ok", "def": {"id": "bel20", "code": "^BFX", "nom": "BEL 20 (Belgique)"}}
A18: sec:marches:idx_us | B18: Indices · États-Unis | C18: ▸ toute la section | K18: {"id": "idx_us", "label": "Indices · États-Unis", "liste": "indices"}
A19: mk:sp500 | B19: Indices · États-Unis | C19: S&P 500 | D19: ^GSPC | G19: Oui | H19: Oui | K19: {"support": "ok", "def": {"id": "sp500", "code": "^GSPC", "nom": "S&P 500"}}
A20: mk:nasdaq100 | B20: Indices · États-Unis | C20: Nasdaq 100 | D20: ^NDX | G20: Oui | K20: {"support": "ok", "def": {"id": "nasdaq100", "code": "^NDX", "nom": "Nasdaq 100"}}
A21: mk:dowjones | B21: Indices · États-Unis | C21: Dow Jones | D21: ^DJI | I21: à vérifier | K21: {"support": "ok", "def": {"id": "dowjones", "code": "^DJI", "nom": "Dow Jones"}}
A22: mk:nasdaq | B22: Indices · États-Unis | C22: Nasdaq Composite | D22: ^IXIC | I22: à vérifier | K22: {"support": "ok", "def": {"id": "nasdaq", "code": "^IXIC", "nom": "Nasdaq Composite"}}
A23: mk:russell2000 | B23: Indices · États-Unis | C23: Russell 2000 | D23: ^RUT | I23: à vérifier | K23: {"support": "ok", "def": {"id": "russell2000", "code": "^RUT", "nom": "Russell 2000"}}
A24: mk:vix | B24: Indices · États-Unis | C24: VIX (volatilité) | D24: ^VIX | I24: à vérifier | K24: {"support": "ok", "def": {"id": "vix", "code": "^VIX", "nom": "VIX (volatilité)"}}
A25: sec:marches:idx_monde | B25: Indices · Monde | C25: ▸ toute la section | K25: {"id": "idx_monde", "label": "Indices · Monde", "liste": "indices"}
A26: mk:monde | B26: Indices · Monde | C26: MSCI World | D26: EUNL.DE | F26: via un ETF en euros | G26: Oui | H26: Oui | K26: {"support": "ok", "def": {"id": "monde", "code": "EUNL.DE", "nom": "MSCI World", "note": "via un ETF en euros"}}
A27: mk:emergents | B27: Indices · Monde | C27: Émergents | D27: IS3N.DE | F27: via un ETF en euros | G27: Oui | K27: {"support": "ok", "def": {"id": "emergents", "code": "IS3N.DE", "nom": "Émergents", "note": "via un ETF en euros"}}
A28: mk:nikkei | B28: Indices · Monde | C28: Nikkei 225 (Japon) | D28: ^N225 | I28: à vérifier | K28: {"support": "ok", "def": {"id": "nikkei", "code": "^N225", "nom": "Nikkei 225 (Japon)"}}
A29: mk:hangseng | B29: Indices · Monde | C29: Hang Seng (Hong Kong) | D29: ^HSI | I29: à vérifier | K29: {"support": "ok", "def": {"id": "hangseng", "code": "^HSI", "nom": "Hang Seng (Hong Kong)"}}
A30: mk:shanghai | B30: Indices · Monde | C30: Shanghai Composite | D30: 000001.SS | I30: à vérifier | K30: {"support": "ok", "def": {"id": "shanghai", "code": "000001.SS", "nom": "Shanghai Composite"}}
A31: mk:sensex | B31: Indices · Monde | C31: Sensex (Inde) | D31: ^BSESN | I31: à vérifier | K31: {"support": "ok", "def": {"id": "sensex", "code": "^BSESN", "nom": "Sensex (Inde)"}}
A32: mk:kospi | B32: Indices · Monde | C32: KOSPI (Corée) | D32: ^KS11 | I32: à vérifier | K32: {"support": "ok", "def": {"id": "kospi", "code": "^KS11", "nom": "KOSPI (Corée)"}}
A33: mk:asx200 | B33: Indices · Monde | C33: ASX 200 (Australie) | D33: ^AXJO | I33: à vérifier | K33: {"support": "ok", "def": {"id": "asx200", "code": "^AXJO", "nom": "ASX 200 (Australie)"}}
A34: mk:tsx | B34: Indices · Monde | C34: TSX (Canada) | D34: ^GSPTSE | I34: à vérifier | K34: {"support": "ok", "def": {"id": "tsx", "code": "^GSPTSE", "nom": "TSX (Canada)"}}
A35: mk:bovespa | B35: Indices · Monde | C35: Bovespa (Brésil) | D35: ^BVSP | I35: à vérifier | K35: {"support": "ok", "def": {"id": "bovespa", "code": "^BVSP", "nom": "Bovespa (Brésil)"}}
A36: sec:marches:matieres | B36: Matières premières | C36: ▸ toute la section | K36: {"id": "matieres", "label": "Matières premières", "liste": "indices"}
A37: mk:or | B37: Matières premières | C37: Or | D37: GC=F | F37: en dollars | G37: Oui | K37: {"support": "ok", "def": {"id": "or", "code": "GC=F", "nom": "Or", "note": "en dollars"}}
A38: mk:brent | B38: Matières premières | C38: Pétrole Brent | D38: BZ=F | F38: en dollars | G38: Oui | K38: {"support": "ok", "def": {"id": "brent", "code": "BZ=F", "nom": "Pétrole Brent", "note": "en dollars"}}
A39: mk:argent | B39: Matières premières | C39: Argent | D39: SI=F | F39: en dollars | I39: à vérifier | K39: {"support": "ok", "def": {"id": "argent", "code": "SI=F", "nom": "Argent", "note": "en dollars"}}
A40: mk:platine | B40: Matières premières | C40: Platine | D40: PL=F | F40: en dollars | I40: à vérifier | K40: {"support": "ok", "def": {"id": "platine", "code": "PL=F", "nom": "Platine", "note": "en dollars"}}
A41: mk:cuivre | B41: Matières premières | C41: Cuivre | D41: HG=F | F41: en dollars | I41: à vérifier | K41: {"support": "ok", "def": {"id": "cuivre", "code": "HG=F", "nom": "Cuivre", "note": "en dollars"}}
...

Sheet Vidéos
A1: module=videos;version=2 | B1: Vidéos · plateformes de streaming
B2: « Oui » = la plateforme apparaît dans les filtres de la page Vidéos. « Abonné » = elle fait partie de « Mes abonnements » par défaut. Seuls les titres inclus dans l'abonnement sont listés (pas la location ni l'achat).
